Workbook

Sheet Dashboard
A1: SDA Installation Dashboard
A2: =TEXT(TODAY(),"DD MMMM YYYY") -> 01 April 2026
A4: Executive Summary
B5: Total Devices | D5: Completed | F5: On Plan | H5: Hold | J5: Pending
B6: =SUM(All_Detail!F2:F740) -> 1592 | D6: =SUMIFS(All_Detail!F2:F740,All_Detail!J2:J740,"Success") -> 505 | F6: =SUMIFS(All_Detail!F2:F740,All_Detail!J2:J740,"On Plan") -> 1081 | H6: =SUMIFS(All_Detail!F2:F740,All_Detail!J2:J740,"Hold") -> 6 | J6: =SUMIFS(All_Detail!F2:F740,All_Detail!J2:J740,"Pending") -> 0
A7: Overall Progress: | B7: =IF(SUM(All_Detail!F2:F740)=0,"",SUM(All_Detail!G2:G740)/SUM(All_Detail!F2:F740)) -> 0.3178392 | C7: Actual Installed: | D7: =SUM(All_Detail!G2:G740) -> 506 | F7: Total Rows: | G7: =COUNTA(All_Detail!B2:B740) -> 739 | H7: Overdue Items: | I7: =SUMPRODUCT((All_Detail!I2:I740<TODAY())*(All_Detail!J2:J740<>"Success")*(All_Detail!F2:F740)) -> 260
A9: Progress by Fabric
A10: Fabric | B10: Total | C10: Done | D10: % Done | E10: Hold | F10: Remaining | G10: Start Date | H10: End Date | I10: On Plan | J10: Overdue Qty
A11: D1-041 | B11: =SUMIFS(All_Detail!F2:F740,All_Detail!B2:B740,A11) -> 710 | C11: =SUMIFS(All_Detail!G2:G740,All_Detail!B2:B740,A11) -> 306 | D11: =IF(B11=0,"",C11/B11) -> 0.43098592 | E11: =SUMIFS(All_Detail!F2:F740,All_Detail!B2:B740,A11,All_Detail!J2:J740,"Hold") -> 4 | F11: =B11-C11 -> 404 | G11: =_xlfn.MINIFS(All_Detail!I2:I740,All_Detail!B2:B740,A11) -> 46063 | H11: =_xlfn.MAXIFS(All_Detail!I2:I740,All_Detail!B2:B740,A11) -> 46174 | I11: =SUMIFS(All_Detail!F2:F740,All_Detail!B2:B740,A11,All_Detail!J2:J740,"On Plan") -> 399 | J11: =SUMPRODUCT((All_Detail!B2:B740=A11)*(All_Detail!I2:I740<TODAY())*(All_Detail!J2:J740<>"Success")*(All_Detail!F2:F740)) -> 243
A12: CFZ | B12: =SUMIFS(All_Detail!F2:F740,All_Detail!B2:B740,A12) -> 187 | C12: =SUMIFS(All_Detail!G2:G740,All_Detail!B2:B740,A12) -> 169 | D12: =IF(B12=0,"",C12/B12) -> 0.90374332 | E12: =SUMIFS(All_Detail!F2:F740,All_Detail!B2:B740,A12,All_Detail!J2:J740,"Hold") -> 2 | F12: =B12-C12 -> 18 | G12: =_xlfn.MINIFS(All_Detail!I2:I740,All_Detail!B2:B740,A12) -> 46063 | H12: =_xlfn.MAXIFS(All_Detail!I2:I740,All_Detail!B2:B740,A12) -> 46174 | I12: =SUMIFS(All_Detail!F2:F740,All_Detail!B2:B740,A12,All_Detail!J2:J740,"On Plan") -> 17 | J12: =SUMPRODUCT((All_Detail!B2:B740=A12)*(All_Detail!I2:I740<TODAY())*(All_Detail!J2:J740<>"Success")*(All_Detail!F2:F740)) -> 17
A13: T1-015 | B13: =SUMIFS(All_Detail!F2:F740,All_Detail!B2:B740,A13) -> 327 | C13: =SUMIFS(All_Detail!G2:G740,All_Detail!B2:B740,A13) -> 2 | D13: =IF(B13=0,"",C13/B13) -> 0.006116208 | E13: =SUMIFS(All_Detail!F2:F740,All_Detail!B2:B740,A13,All_Detail!J2:J740,"Hold") -> 0 | F13: =B13-C13 -> 325 | G13: =_xlfn.MINIFS(All_Detail!I2:I740,All_Detail!B2:B740,A13) -> 46063 | H13: =_xlfn.MAXIFS(All_Detail!I2:I740,All_Detail!B2:B740,A13) -> 46169 | I13: =SUMIFS(All_Detail!F2:F740,All_Detail!B2:B740,A13,All_Detail!J2:J740,"On Plan") -> 325 | J13: =SUMPRODUCT((All_Detail!B2:B740=A13)*(All_Detail!I2:I740<TODAY())*(All_Detail!J2:J740<>"Success")*(All_Detail!F2:F740)) -> 0
A14: D1-091 | B14: =SUMIFS(All_Detail!F2:F740,All_Detail!B2:B740,A14) -> 147 | C14: =SUMIFS(All_Detail!G2:G740,All_Detail!B2:B740,A14) -> 2 | D14: =IF(B14=0,"",C14/B14) -> 0.013605442 | E14: =SUMIFS(All_Detail!F2:F740,All_Detail!B2:B740,A14,All_Detail!J2:J740,"Hold") -> 0 | F14: =B14-C14 -> 145 | G14: =_xlfn.MINIFS(All_Detail!I2:I740,All_Detail!B2:B740,A14) -> 46063 | H14: =_xlfn.MAXIFS(All_Detail!I2:I740,All_Detail!B2:B740,A14) -> 46181 | I14: =SUMIFS(All_Detail!F2:F740,All_Detail!B2:B740,A14,All_Detail!J2:J740,"On Plan") -> 145 | J14: =SUMPRODUCT((All_Detail!B2:B740=A14)*(All_Detail!I2:I740<TODAY())*(All_Detail!J2:J740<>"Success")*(All_Detail!F2:F740)) -> 0
A15: RFF | B15: =SUMIFS(All_Detail!F2:F740,All_Detail!B2:B740,A15) -> 99 | C15: =SUMIFS(All_Detail!G2:G740,All_Detail!B2:B740,A15) -> 2 | D15: =IF(B15=0,"",C15/B15) -> 0.02020202 | E15: =SUMIFS(All_Detail!F2:F740,All_Detail!B2:B740,A15,All_Detail!J2:J740,"Hold") -> 0 | F15: =B15-C15 -> 97 | G15: =_xlfn.MINIFS(All_Detail!I2:I740,All_Detail!B2:B740,A15) -> 46063 | H15: =_xlfn.MAXIFS(All_Detail!I2:I740,All_Detail!B2:B740,A15) -> 46188 | I15: =SUMIFS(All_Detail!F2:F740,All_Detail!B2:B740,A15,All_Detail!J2:J740,"On Plan") -> 97 | J15: =SUMPRODUCT((All_Detail!B2:B740=A15)*(All_Detail!I2:I740<TODAY())*(All_Detail!J2:J740<>"Success")*(All_Detail!F2:F740)) -> 0
A16: AMF | B16: =SUMIFS(All_Detail!F2:F740,All_Detail!B2:B740,A16) -> 114 | C16: =SUMIFS(All_Detail!G2:G740,All_Detail!B2:B740,A16) -> 23 | D16: =IF(B16=0,"",C16/B16) -> 0.20175439 | E16: =SUMIFS(All_Detail!F2:F740,All_Detail!B2:B740,A16,All_Detail!J2:J740,"Hold") -> 0 | F16: =B16-C16 -> 91 | G16: =_xlfn.MINIFS(All_Detail!I2:I740,All_Detail!B2:B740,A16) -> 46063 | H16: =_xlfn.MAXIFS(All_Detail!I2:I740,All_Detail!B2:B740,A16) -> 46195 | I16: =SUMIFS(All_Detail!F2:F740,All_Detail!B2:B740,A16,All_Detail!J2:J740,"On Plan") -> 92 | J16: =SUMPRODUCT((All_Detail!B2:B740=A16)*(All_Detail!I2:I740<TODAY())*(All_Detail!J2:J740<>"Success")*(All_Detail!F2:F740)) -> 0
A17: PPW | B17: =SUMIFS(All_Detail!F2:F740,All_Detail!B2:B740,A17) -> 8 | C17: =SUMIFS(All_Detail!G2:G740,All_Detail!B2:B740,A17) -> 2 | D17: =IF(B17=0,"",C17/B17) -> 0.25 | E17: =SUMIFS(All_Detail!F2:F740,All_Detail!B2:B740,A17,All_Detail!J2:J740,"Hold") -> 0 | F17: =B17-C17 -> 6 | G17: =_xlfn.MINIFS(All_Detail!I2:I740,All_Detail!B2:B740,A17) -> 46063 | H17: =_xlfn.MAXIFS(All_Detail!I2:I740,All_Detail!B2:B740,A17) -> 46196 | I17: =SUMIFS(All_Detail!F2:F740,All_Detail!B2:B740,A17,All_Detail!J2:J740,"On Plan") -> 6 | J17: =SUMPRODUCT((All_Detail!B2:B740=A17)*(All_Detail!I2:I740<TODAY())*(All_Detail!J2:J740<>"Success")*(All_Detail!F2:F740)) -> 0
A18: TOTAL | B18: =SUM(B11:B17) -> 1592 | C18: =SUM(C11:C17) -> 506 | D18: =IF(B18=0,"",C18/B18) -> 0.3178392 | E18: =SUM(E11:E17) -> 6 | F18: =SUM(F11:F17) -> 1086 | G18: =MIN(G11:G17) -> 46063 | H18: =MAX(H11:H17) -> 46196 | I18: =SUM(I11:I17) -> 1081 | J18: =SUM(J11:J17) -> 260
A20: Device Category Breakdown
A21: Category | B21: Total | C21: Done | D21: % Done | E21: Remaining | F21: Hold | G21: Overdue Qty
A22: Switch | B22: =SUMIFS(All_Detail!F2:F740,All_Detail!O2:O740,A22) -> 1121 | C22: =SUMIFS(All_Detail!G2:G740,All_Detail!O2:O740,A22) -> 407 | D22: =IF(B22=0,"",C22/B22) -> 0.36306869 | E22: =B22-C22 -> 714 | F22: =SUMIFS(All_Detail!F2:F740,All_Detail!O2:O740,A22,All_Detail!J2:J740,"Hold") -> 6 | G22: =SUMPRODUCT((All_Detail!O2:O740=A22)*(All_Detail!I2:I740<TODAY())*(All_Detail!J2:J740<>"Success")*(All_Detail!F2:F740)) -> 81
A23: AP | B23: =SUMIFS(All_Detail!F2:F740,All_Detail!O2:O740,A23) -> 445 | C23: =SUMIFS(All_Detail!G2:G740,All_Detail!O2:O740,A23) -> 75 | D23: =IF(B23=0,"",C23/B23) -> 0.16853933 | E23: =B23-C23 -> 370 | F23: =SUMIFS(All_Detail!F2:F740,All_Detail!O2:O740,A23,All_Detail!J2:J740,"Hold") -> 0 | G23: =SUMPRODUCT((All_Detail!O2:O740=A23)*(All_Detail!I2:I740<TODAY())*(All_Detail!J2:J740<>"Success")*(All_Detail!F2:F740)) -> 177
A24: Infra | B24: =SUMIFS(All_Detail!F2:F740,All_Detail!O2:O740,A24) -> 26 | C24: =SUMIFS(All_Detail!G2:G740,All_Detail!O2:O740,A24) -> 24 | D24: =IF(B24=0,"",C24/B24) -> 0.92307692 | E24: =B24-C24 -> 2 | F24: =SUMIFS(All_Detail!F2:F740,All_Detail!O2:O740,A24,All_Detail!J2:J740,"Hold") -> 0 | G24: =SUMPRODUCT((All_Detail!O2:O740=A24)*(All_Detail!I2:I740<TODAY())*(All_Detail!J2:J740<>"Success")*(All_Detail!F2:F740)) -> 2
A26: Progress by Fabric - Switch vs AP
A27: Fabric | B27: SW Total | C27: SW Done | D27: SW % | E27: AP Total | F27: AP Done | G27: AP % | H27: Infra Total | I27: Infra Done | J27: Infra %
A28: D1-041 | B28: =SUMIFS(All_Detail!F$2:F$740,All_Detail!B$2:B$740,A28,All_Detail!O$2:O$740,"Switch") -> 410 | C28: =SUMIFS(All_Detail!G$2:G$740,All_Detail!B$2:B$740,A28,All_Detail!O$2:O$740,"Switch") -> 253 | D28: =IF(B28=0,"",C28/B28) -> 0.61707317 | E28: =SUMIFS(All_Detail!F$2:F$740,All_Detail!B$2:B$740,A28,All_Detail!O$2:O$740,"AP") -> 290 | F28: =SUMIFS(All_Detail!G$2:G$740,All_Detail!B$2:B$740,A28,All_Detail!O$2:O$740,"AP") -> 43 | G28: =IF(E28=0,"",F28/E28) -> 0.14827586 | H28: =SUMIFS(All_Detail!F$2:F$740,All_Detail!B$2:B$740,A28,All_Detail!O$2:O$740,"Infra") -> 10 | I28: =SUMIFS(All_Detail!G$2:G$740,All_Detail!B$2:B$740,A28,All_Detail!O$2:O$740,"Infra") -> 10 | J28: =IF(H28=0,"",I28/H28) -> 1
A29: CFZ | B29: =SUMIFS(All_Detail!F$2:F$740,All_Detail!B$2:B$740,A29,All_Detail!O$2:O$740,"Switch") -> 156 | C29: =SUMIFS(All_Detail!G$2:G$740,All_Detail!B$2:B$740,A29,All_Detail!O$2:O$740,"Switch") -> 141 | D29: =IF(B29=0,"",C29/B29) -> 0.90384615 | E29: =SUMIFS(All_Detail!F$2:F$740,All_Detail!B$2:B$740,A29,All_Detail!O$2:O$740,"AP") -> 25 | F29: =SUMIFS(All_Detail!G$2:G$740,All_Detail!B$2:B$740,A29,All_Detail!O$2:O$740,"AP") -> 24 | G29: =IF(E29=0,"",F29/E29) -> 0.96 | H29: =SUMIFS(All_Detail!F$2:F$740,All_Detail!B$2:B$740,A29,All_Detail!O$2:O$740,"Infra") -> 6 | I29: =SUMIFS(All_Detail!G$2:G$740,All_Detail!B$2:B$740,A29,All_Detail!O$2:O$740,"Infra") -> 4 | J29: =IF(H29=0,"",I29/H29) -> 0.66666667
A30: T1-015 | B30: =SUMIFS(All_Detail!F$2:F$740,All_Detail!B$2:B$740,A30,All_Detail!O$2:O$740,"Switch") -> 281 | C30: =SUMIFS(All_Detail!G$2:G$740,All_Detail!B$2:B$740,A30,All_Detail!O$2:O$740,"Switch") -> 0 | D30: =IF(B30=0,"",C30/B30) -> 0 | E30: =SUMIFS(All_Detail!F$2:F$740,All_Detail!B$2:B$740,A30,All_Detail!O$2:O$740,"AP") -> 44 | F30: =SUMIFS(All_Detail!G$2:G$740,All_Detail!B$2:B$740,A30,All_Detail!O$2:O$740,"AP") -> 0 | G30: =IF(E30=0,"",F30/E30) -> 0 | H30: =SUMIFS(All_Detail!F$2:F$740,All_Detail!B$2:B$740,A30,All_Detail!O$2:O$740,"Infra") -> 2 | I30: =SUMIFS(All_Detail!G$2:G$740,All_Detail!B$2:B$740,A30,All_Detail!O$2:O$740,"Infra") -> 2 | J30: =IF(H30=0,"",I30/H30) -> 1
A31: D1-091 | B31: =SUMIFS(All_Detail!F$2:F$740,All_Detail!B$2:B$740,A31,All_Detail!O$2:O$740,"Switch") -> 134 | C31: =SUMIFS(All_Detail!G$2:G$740,All_Detail!B$2:B$740,A31,All_Detail!O$2:O$740,"Switch") -> 0 | D31: =IF(B31=0,"",C31/B31) -> 0 | E31: =SUMIFS(All_Detail!F$2:F$740,All_Detail!B$2:B$740,A31,All_Detail!O$2:O$740,"AP") -> 11 | F31: =SUMIFS(All_Detail!G$2:G$740,All_Detail!B$2:B$740,A31,All_Detail!O$2:O$740,"AP") -> 0 | G31: =IF(E31=0,"",F31/E31) -> 0 | H31: =SUMIFS(All_Detail!F$2:F$740,All_Detail!B$2:B$740,A31,All_Detail!O$2:O$740,"Infra") -> 2 | I31: =SUMIFS(All_Detail!G$2:G$740,All_Detail!B$2:B$740,A31,All_Detail!O$2:O$740,"Infra") -> 2 | J31: =IF(H31=0,"",I31/H31) -> 1
A32: RFF | B32: =SUMIFS(All_Detail!F$2:F$740,All_Detail!B$2:B$740,A32,All_Detail!O$2:O$740,"Switch") -> 65 | C32: =SUMIFS(All_Detail!G$2:G$740,All_Detail!B$2:B$740,A32,All_Detail!O$2:O$740,"Switch") -> 0 | D32: =IF(B32=0,"",C32/B32) -> 0 | E32: =SUMIFS(All_Detail!F$2:F$740,All_Detail!B$2:B$740,A32,All_Detail!O$2:O$740,"AP") -> 32 | F32: =SUMIFS(All_Detail!G$2:G$740,All_Detail!B$2:B$740,A32,All_Detail!O$2:O$740,"AP") -> 0 | G32: =IF(E32=0,"",F32/E32) -> 0 | H32: =SUMIFS(All_Detail!F$2:F$740,All_Detail!B$2:B$740,A32,All_Detail!O$2:O$740,"Infra") -> 2 | I32: =SUMIFS(All_Detail!G$2:G$740,All_Detail!B$2:B$740,A32,All_Detail!O$2:O$740,"Infra") -> 2 | J32: =IF(H32=0,"",I32/H32) -> 1
A33: AMF | B33: =SUMIFS(All_Detail!F$2:F$740,All_Detail!B$2:B$740,A33,All_Detail!O$2:O$740,"Switch") -> 69 | C33: =SUMIFS(All_Detail!G$2:G$740,All_Detail!B$2:B$740,A33,All_Detail!O$2:O$740,"Switch") -> 13 | D33: =IF(B33=0,"",C33/B33) -> 0.1884058 | E33: =SUMIFS(All_Detail!F$2:F$740,All_Detail!B$2:B$740,A33,All_Detail!O$2:O$740,"AP") -> 43 | F33: =SUMIFS(All_Detail!G$2:G$740,All_Detail!B$2:B$740,A33,All_Detail!O$2:O$740,"AP") -> 8 | G33: =IF(E33=0,"",F33/E33) -> 0.18604651 | H33: =SUMIFS(All_Detail!F$2:F$740,All_Detail!B$2:B$740,A33,All_Detail!O$2:O$740,"Infra") -> 2 | I33: =SUMIFS(All_Detail!G$2:G$740,All_Detail!B$2:B$740,A33,All_Detail!O$2:O$740,"Infra") -> 2 | J33: =IF(H33=0,"",I33/H33) -> 1
A34: PPW | B34: =SUMIFS(All_Detail!F$2:F$740,All_Detail!B$2:B$740,A34,All_Detail!O$2:O$740,"Switch") -> 6 | C34: =SUMIFS(All_Detail!G$2:G$740,All_Detail!B$2:B$740,A34,All_Detail!O$2:O$740,"Switch") -> 0 | D34: =IF(B34=0,"",C34/B34) -> 0 | E34: =SUMIFS(All_Detail!F$2:F$740,All_Detail!B$2:B$740,A34,All_Detail!O$2:O$740,"AP") -> 0 | F34: =SUMIFS(All_Detail!G$2:G$740,All_Detail!B$2:B$740,A34,All_Detail!O$2:O$740,"AP") -> 0 | G34: =IF(E34=0,"",F34/E34) | H34: =SUMIFS(All_Detail!F$2:F$740,All_Detail!B$2:B$740,A34,All_Detail!O$2:O$740,"Infra") -> 2 | I34: =SUMIFS(All_Detail!G$2:G$740,All_Detail!B$2:B$740,A34,All_Detail!O$2:O$740,"Infra") -> 2 | J34: =IF(H34=0,"",I34/H34) -> 1
A35: TOTAL | B35: =SUM(B28:B34) -> 1121 | C35: =SUM(C28:C34) -> 407 | D35: =IF(B35=0,"",C35/B35) -> 0.36306869 | E35: =SUM(E28:E34) -> 445 | F35: =SUM(F28:F34) -> 75 | G35: =IF(E35=0,"",F35/E35) -> 0.16853933 | H35: =SUM(H28:H34) -> 26 | I35: =SUM(I28:I34) -> 24 | J35: =IF(H35=0,"",I35/H35) -> 0.92307692
A39: Weekly Installation Velocity
A40: Week | B40: Dates | C40: Planned | D40: Actual | E40: Cum.Plan | F40: Cum.Actual | G40: SW Plan | H40: SW Actual | I40: AP Plan | J40: AP Actual
A41: 7 | B41: =TEXT(DATE(2025,12,29)+(A41-1)*7,"DD MMM")&" - "&TEXT(DATE(2025,12,29)+(A41-1)*7+6,"DD MMM") -> 09 Feb - 15 Feb | C41: =SUMPRODUCT((_xlfn.ISOWEEKNUM(All_Detail!I$2:I$740)=A41)*(All_Detail!F$2:F$740)) -> 50 | D41: =SUMPRODUCT((_xlfn.ISOWEEKNUM(All_Detail!H$2:H$740)=A41)*(All_Detail!G$2:G$740)) -> 80 | E41: =SUM(C41) -> 50 | F41: =SUM(D41) -> 80 | G41: =SUMPRODUCT((_xlfn.ISOWEEKNUM(All_Detail!I$2:I$740)=A41)*(All_Detail!O$2:O$740="Switch")*(All_Detail!F$2:F$740)) -> 28 | H41: =SUMPRODUCT((_xlfn.ISOWEEKNUM(All_Detail!H$2:H$740)=A41)*(All_Detail!O$2:O$740="Switch")*(All_Detail!G$2:G$740)) -> 32 | I41: =SUMPRODUCT((_xlfn.ISOWEEKNUM(All_Detail!I$2:I$740)=A41)*(All_Detail!O$2:O$740="AP")*(All_Detail!F$2:F$740)) -> 0 | J41: =SUMPRODUCT((_xlfn.ISOWEEKNUM(All_Detail!H$2:H$740)=A41)*(All_Detail!O$2:O$740="AP")*(All_Detail!G$2:G$740)) -> 24
A42: 8 | B42: =TEXT(DATE(2025,12,29)+(A42-1)*7,"DD MMM")&" - "&TEXT(DATE(2025,12,29)+(A42-1)*7+6,"DD MMM") -> 16 Feb - 22 Feb | C42: =SUMPRODUCT((_xlfn.ISOWEEKNUM(All_Detail!I$2:I$740)=A42)*(All_Detail!F$2:F$740)) -> 103 | D42: =SUMPRODUCT((_xlfn.ISOWEEKNUM(All_Detail!H$2:H$740)=A42)*(All_Detail!G$2:G$740)) -> 99 | E42: =SUM(C41:C42) -> 153 | F42: =SUM(D41:D42) -> 179 | G42: =SUMPRODUCT((_xlfn.ISOWEEKNUM(All_Detail!I$2:I$740)=A42)*(All_Detail!O$2:O$740="Switch")*(All_Detail!F$2:F$740)) -> 60 | H42: =SUMPRODUCT((_xlfn.ISOWEEKNUM(All_Detail!H$2:H$740)=A42)*(All_Detail!O$2:O$740="Switch")*(All_Detail!G$2:G$740)) -> 56 | I42: =SUMPRODUCT((_xlfn.ISOWEEKNUM(All_Detail!I$2:I$740)=A42)*(All_Detail!O$2:O$740="AP")*(All_Detail!F$2:F$740)) -> 43 | J42: =SUMPRODUCT((_xlfn.ISOWEEKNUM(All_Detail!H$2:H$740)=A42)*(All_Detail!O$2:O$740="AP")*(All_Detail!G$2:G$740)) -> 43
A43: 9 | B43: =TEXT(DATE(2025,12,29)+(A43-1)*7,"DD MMM")&" - "&TEXT(DATE(2025,12,29)+(A43-1)*7+6,"DD MMM") -> 23 Feb - 01 Mar | C43: =SUMPRODUCT((_xlfn.ISOWEEKNUM(All_Detail!I$2:I$740)=A43)*(All_Detail!F$2:F$740)) -> 94 | D43: =SUMPRODUCT((_xlfn.ISOWEEKNUM(All_Detail!H$2:H$740)=A43)*(All_Detail!G$2:G$740)) -> 70 | E43: =SUM(C41:C43) -> 247 | F43: =SUM(D41:D43) -> 249 | G43: =SUMPRODUCT((_xlfn.ISOWEEKNUM(All_Detail!I$2:I$740)=A43)*(All_Detail!O$2:O$740="Switch")*(All_Detail!F$2:F$740)) -> 70 | H43: =SUMPRODUCT((_xlfn.ISOWEEKNUM(All_Detail!H$2:H$740)=A43)*(All_Detail!O$2:O$740="Switch")*(All_Detail!G$2:G$740)) -> 70 | I43: =SUMPRODUCT((_xlfn.ISOWEEKNUM(All_Detail!I$2:I$740)=A43)*(All_Detail!O$2:O$740="AP")*(All_Detail!F$2:F$740)) -> 24 | J43: =SUMPRODUCT((_xlfn.ISOWEEKNUM(All_Detail!H$2:H$740)=A43)*(All_Detail!O$2:O$740="AP")*(All_Detail!G$2:G$740)) -> 0
A44: 10 | B44: =TEXT(DATE(2025,12,29)+(A44-1)*7,"DD MMM")&" - "&TEXT(DATE(2025,12,29)+(A44-1)*7+6,"DD MMM") -> 02 Mar - 08 Mar | C44: =SUMPRODUCT((_xlfn.ISOWEEKNUM(All_Detail!I$2:I$740)=A44)*(All_Detail!F$2:F$740)) -> 41 | D44: =SUMPRODUCT((_xlfn.ISOWEEKNUM(All_Detail!H$2:H$740)=A44)*(All_Detail!G$2:G$740)) -> 39 | E44: =SUM(C41:C44) -> 288 | F44: =SUM(D41:D44) -> 288 | G44: =SUMPRODUCT((_xlfn.ISOWEEKNUM(All_Detail!I$2:I$740)=A44)*(All_Detail!O$2:O$740="Switch")*(All_Detail!F$2:F$740)) -> 39 | H44: =SUMPRODUCT((_xlfn.ISOWEEKNUM(All_Detail!H$2:H$740)=A44)*(All_Detail!O$2:O$740="Switch")*(All_Detail!G$2:G$740)) -> 39 | I44: =SUMPRODUCT((_xlfn.ISOWEEKNUM(All_Detail!I$2:I$740)=A44)*(All_Detail!O$2:O$740="AP")*(All_Detail!F$2:F$740)) -> 0 | J44: =SUMPRODUCT((_xlfn.ISOWEEKNUM(All_Detail!H$2:H$740)=A44)*(All_Detail!O$2:O$740="AP")*(All_Detail!G$2:G$740)) -> 0
A45: 11 | B45: =TEXT(DATE(2025,12,29)+(A45-1)*7,"DD MMM")&" - "&TEXT(DATE(2025,12,29)+(A45-1)*7+6,"DD MMM") -> 09 Mar - 15 Mar | C45: =SUMPRODUCT((_xlfn.ISOWEEKNUM(All_Detail!I$2:I$740)=A45)*(All_Detail!F$2:F$740)) -> 94 | D45: =SUMPRODUCT((_xlfn.ISOWEEKNUM(All_Detail!H$2:H$740)=A45)*(All_Detail!G$2:G$740)) -> 93 | E45: =SUM(C41:C45) -> 382 | F45: =SUM(D41:D45) -> 381 | G45: =SUMPRODUCT((_xlfn.ISOWEEKNUM(All_Detail!I$2:I$740)=A45)*(All_Detail!O$2:O$740="Switch")*(All_Detail!F$2:F$740)) -> 94 | H45: =SUMPRODUCT((_xlfn.ISOWEEKNUM(All_Detail!H$2:H$740)=A45)*(All_Detail!O$2:O$740="Switch")*(All_Detail!G$2:G$740)) -> 93 | I45: =SUMPRODUCT((_xlfn.ISOWEEKNUM(All_Detail!I$2:I$740)=A45)*(All_Detail!O$2:O$740="AP")*(All_Detail!F$2:F$740)) -> 0 | J45: =SUMPRODUCT((_xlfn.ISOWEEKNUM(All_Detail!H$2:H$740)=A45)*(All_Detail!O$2:O$740="AP")*(All_Detail!G$2:G$740)) -> 0
A46: 12 | B46: =TEXT(DATE(2025,12,29)+(A46-1)*7,"DD MMM")&" - "&TEXT(DATE(2025,12,29)+(A46-1)*7+6,"DD MMM") -> 16 Mar - 22 Mar | C46: =SUMPRODUCT((_xlfn.ISOWEEKNUM(All_Detail!I$2:I$740)=A46)*(All_Detail!F$2:F$740)) -> 60 | D46: =SUMPRODUCT((_xlfn.ISOWEEKNUM(All_Detail!H$2:H$740)=A46)*(All_Detail!G$2:G$740)) -> 80 | E46: =SUM(C41:C46) -> 442 | F46: =SUM(D41:D46) -> 461 | G46: =SUMPRODUCT((_xlfn.ISOWEEKNUM(All_Detail!I$2:I$740)=A46)*(All_Detail!O$2:O$740="Switch")*(All_Detail!F$2:F$740)) -> 60 | H46: =SUMPRODUCT((_xlfn.ISOWEEKNUM(All_Detail!H$2:H$740)=A46)*(All_Detail!O$2:O$740="Switch")*(All_Detail!G$2:G$740)) -> 80 | I46: =SUMPRODUCT((_xlfn.ISOWEEKNUM(All_Detail!I$2:I$740)=A46)*(All_Detail!O$2:O$740="AP")*(All_Detail!F$2:F$740)) -> 0 | J46: =SUMPRODUCT((_xlfn.ISOWEEKNUM(All_Detail!H$2:H$740)=A46)*(All_Detail!O$2:O$740="AP")*(All_Detail!G$2:G$740)) -> 0
A47: 13 | B47: =TEXT(DATE(2025,12,29)+(A47-1)*7,"DD MMM")&" - "&TEXT(DATE(2025,12,29)+(A47-1)*7+6,"DD MMM") -> 23 Mar - 29 Mar | C47: =SUMPRODUCT((_xlfn.ISOWEEKNUM(All_Detail!I$2:I$740)=A47)*(All_Detail!F$2:F$740)) -> 241 | D47: =SUMPRODUCT((_xlfn.ISOWEEKNUM(All_Detail!H$2:H$740)=A47)*(All_Detail!G$2:G$740)) -> 42 | E47: =SUM(C41:C47) -> 683 | F47: =SUM(D41:D47) -> 503 | G47: =SUMPRODUCT((_xlfn.ISOWEEKNUM(All_Detail!I$2:I$740)=A47)*(All_Detail!O$2:O$740="Switch")*(All_Detail!F$2:F$740)) -> 62 | H47: =SUMPRODUCT((_xlfn.ISOWEEKNUM(All_Detail!H$2:H$740)=A47)*(All_Detail!O$2:O$740="Switch")*(All_Detail!G$2:G$740)) -> 34 | I47: =SUMPRODUCT((_xlfn.ISOWEEKNUM(All_Detail!I$2:I$740)=A47)*(All_Detail!O$2:O$740="AP")*(All_Detail!F$2:F$740)) -> 177 | J47: =SUMPRODUCT((_xlfn.ISOWEEKNUM(All_Detail!H$2:H$740)=A47)*(All_Detail!O$2:O$740="AP")*(All_Detail!G$2:G$740)) -> 8
...

Sheet All_Detail
A1: No. | B1: Fabric | C1: Location | D1: Room | E1: Device Type | F1: Qty | G1: Qty. Success | H1: Install Date | I1: Scheduled Date | J1: Status | K1: Qty. Remaining | L1: % Complete | M1: Days Until Due | N1: Week | O1: Category | P1: Remark
A2: 703 | B2: AMF | C2: AMF4 | D2: AMF4-FL.1 | E2: Access Switch Type 2 | F2: 2 | G2: 2 | H2: 46109 | I2: 46189 | J2: Success | K2: =F2-G2 -> 0 | L2: =IF(F2=0,"",G2/F2) -> 1 | M2: =I2-TODAY() -> 76 | N2: =_xlfn.ISOWEEKNUM(I2) -> 25 | O2: =IF(ISNUMBER(SEARCH("Access Point",E2)),"AP",IF(OR(ISNUMBER(SEARCH("Switch",E2)),ISNUMBER(SEARCH("Control Type",E2))),"Switch","Infra")) -> Switch
A3: 688 | B3: AMF | C3: AMF1 | D3: - | E3: Access Point | F3: 18 | I3: 46189 | J3: On Plan | K3: =F3-G3 -> 18 | L3: =IF(F3=0,"",G3/F3) -> 0 | M3: =I3-TODAY() -> 76 | N3: =_xlfn.ISOWEEKNUM(I3) -> 25 | O3: =IF(ISNUMBER(SEARCH("Access Point",E3)),"AP",IF(OR(ISNUMBER(SEARCH("Switch",E3)),ISNUMBER(SEARCH("Control Type",E3))),"Switch","Infra")) -> AP
A4: 704 | B4: AMF | C4: AMF4 | D4: งานซ่อมบำรุงยานยนต์ | E4: Access Switch Type 4 | F4: 1 | G4: 2 | H4: 46109 | I4: 46189 | J4: Success | K4: =F4-G4 -> -1 | L4: =IF(F4=0,"",G4/F4) -> 2 | M4: =I4-TODAY() -> 76 | N4: =_xlfn.ISOWEEKNUM(I4) -> 25 | O4: =IF(ISNUMBER(SEARCH("Access Point",E4)),"AP",IF(OR(ISNUMBER(SEARCH("Switch",E4)),ISNUMBER(SEARCH("Control Type",E4))),"Switch","Infra")) -> Switch | P4: *Type 4 ไป 1 ตัว ห้องส่วนสนามบิน N5-AMF41-VS02
A5: 690 | B5: AMF | C5: AMF1 | D5: AMF1 FL.2 | E5: Wireless Controller | F5: 2 | G5: 2 | H5: 46063 | I5: 46063 | J5: Success | K5: =F5-G5 -> 0 | L5: =IF(F5=0,"",G5/F5) -> 1 | M5: =I5-TODAY() -> -50 | N5: =_xlfn.ISOWEEKNUM(I5) -> 7 | O5: =IF(ISNUMBER(SEARCH("Access Point",E5)),"AP",IF(OR(ISNUMBER(SEARCH("Switch",E5)),ISNUMBER(SEARCH("Control Type",E5))),"Switch","Infra")) -> Infra
A6: 689 | B6: AMF | C6: AMF1 | D6: AMF1 FL.2 | E6: Distribute Switch Type 1 | F6: 2 | G6: 2 | H6: 46105 | I6: 46190 | J6: Success | K6: =F6-G6 -> 0 | L6: =IF(F6=0,"",G6/F6) -> 1 | M6: =I6-TODAY() -> 77 | N6: =_xlfn.ISOWEEKNUM(I6) -> 25 | O6: =IF(ISNUMBER(SEARCH("Access Point",E6)),"AP",IF(OR(ISNUMBER(SEARCH("Switch",E6)),ISNUMBER(SEARCH("Control Type",E6))),"Switch","Infra")) -> Switch
A7: 705 | B7: AMF | C7: AMF4 | D7: ส่วนบำรุงพื้นที่และสนับสนุนเครื่องทุนแรง | E7: Access Switch Type 4 | F7: 2 | G7: 2 | H7: 46109 | I7: 46189 | J7: Success | K7: =F7-G7 -> 0 | L7: =IF(F7=0,"",G7/F7) -> 1 | M7: =I7-TODAY() -> 76 | N7: =_xlfn.ISOWEEKNUM(I7) -> 25 | O7: =IF(ISNUMBER(SEARCH("Access Point",E7)),"AP",IF(OR(ISNUMBER(SEARCH("Switch",E7)),ISNUMBER(SEARCH("Control Type",E7))),"Switch","Infra")) -> Switch
A8: 706 | B8: AMF | C8: AMF4 | D8: ส่วนบำรุงพื้นที่และสนับสนุนเครื่องทุนแรง Room | E8: Access Switch Type 2 | F8: 3 | G8: 3 | H8: 46109 | I8: 46190 | J8: Success | K8: =F8-G8 -> 0 | L8: =IF(F8=0,"",G8/F8) -> 1 | M8: =I8-TODAY() -> 77 | N8: =_xlfn.ISOWEEKNUM(I8) -> 25 | O8: =IF(ISNUMBER(SEARCH("Access Point",E8)),"AP",IF(OR(ISNUMBER(SEARCH("Switch",E8)),ISNUMBER(SEARCH("Control Type",E8))),"Switch","Infra")) -> Switch
A9: 115 | B9: D1-041 | C9: Concourse D | D9: D4-009 | E9: Access Switch Type 4 | F9: 1 | G9: 1 | H9: 46108 | I9: 46112 | J9: Success | K9: =F9-G9 -> 0 | L9: =IF(F9=0,"",G9/F9) -> 1 | M9: =I9-TODAY() -> -1 | N9: =_xlfn.ISOWEEKNUM(I9) -> 14 | O9: =IF(ISNUMBER(SEARCH("Access Point",E9)),"AP",IF(OR(ISNUMBER(SEARCH("Switch",E9)),ISNUMBER(SEARCH("Control Type",E9))),"Switch","Infra")) -> Switch
A10: 695 | B10: AMF | C10: AMF1 | D10: AMF12 Core Room | E10: Aggregation Switch Type 2 | F10: 2 | G10: 2 | H10: 46105 | I10: 46191 | J10: Success | K10: =F10-G10 -> 0 | L10: =IF(F10=0,"",G10/F10) -> 1 | M10: =I10-TODAY() -> 78 | N10: =_xlfn.ISOWEEKNUM(I10) -> 25 | O10: =IF(ISNUMBER(SEARCH("Access Point",E10)),"AP",IF(OR(ISNUMBER(SEARCH("Switch",E10)),ISNUMBER(SEARCH("Control Type",E10))),"Switch","Infra")) -> Switch
A11: 114 | B11: D1-041 | C11: Concourse D | D11: D4-009 | E11: Access Switch Type 2 | F11: 1 | G11: 1 | H11: 46108 | I11: 46112 | J11: Success | K11: =F11-G11 -> 0 | L11: =IF(F11=0,"",G11/F11) -> 1 | M11: =I11-TODAY() -> -1 | N11: =_xlfn.ISOWEEKNUM(I11) -> 14 | O11: =IF(ISNUMBER(SEARCH("Access Point",E11)),"AP",IF(OR(ISNUMBER(SEARCH("Switch",E11)),ISNUMBER(SEARCH("Control Type",E11))),"Switch","Infra")) -> Switch
A12: 118 | B12: D1-041 | C12: Concourse D | D12: D4-074 | E12: Access Switch Type 2 | F12: 1 | G12: 1 | H12: 46108 | I12: 46112 | J12: Success | K12: =F12-G12 -> 0 | L12: =IF(F12=0,"",G12/F12) -> 1 | M12: =I12-TODAY() -> -1 | N12: =_xlfn.ISOWEEKNUM(I12) -> 14 | O12: =IF(ISNUMBER(SEARCH("Access Point",E12)),"AP",IF(OR(ISNUMBER(SEARCH("Switch",E12)),ISNUMBER(SEARCH("Control Type",E12))),"Switch","Infra")) -> Switch
A13: 120 | B13: D1-041 | C13: Concourse D | D13: D4-081 | E13: Access Switch Type 2 | F13: 1 | G13: 1 | H13: 46108 | I13: 46112 | J13: Success | K13: =F13-G13 -> 0 | L13: =IF(F13=0,"",G13/F13) -> 1 | M13: =I13-TODAY() -> -1 | N13: =_xlfn.ISOWEEKNUM(I13) -> 14 | O13: =IF(ISNUMBER(SEARCH("Access Point",E13)),"AP",IF(OR(ISNUMBER(SEARCH("Switch",E13)),ISNUMBER(SEARCH("Control Type",E13))),"Switch","Infra")) -> Switch
A14: 146 | B14: D1-041 | C14: Concourse A | D14: A2-009 | E14: Access Switch Type 4 | F14: 1 | G14: 1 | H14: 46107 | I14: 46129 | J14: Success | K14: =F14-G14 -> 0 | L14: =IF(F14=0,"",G14/F14) -> 1 | M14: =I14-TODAY() -> 16 | N14: =_xlfn.ISOWEEKNUM(I14) -> 16 | O14: =IF(ISNUMBER(SEARCH("Access Point",E14)),"AP",IF(OR(ISNUMBER(SEARCH("Switch",E14)),ISNUMBER(SEARCH("Control Type",E14))),"Switch","Infra")) -> Switch
A15: 145 | B15: D1-041 | C15: Concourse A | D15: A2-009 | E15: Access Switch Type 2 | F15: 2 | G15: 2 | H15: 46107 | I15: 46129 | J15: Success | K15: =F15-G15 -> 0 | L15: =IF(F15=0,"",G15/F15) -> 1 | M15: =I15-TODAY() -> 16 | N15: =_xlfn.ISOWEEKNUM(I15) -> 16 | O15: =IF(ISNUMBER(SEARCH("Access Point",E15)),"AP",IF(OR(ISNUMBER(SEARCH("Switch",E15)),ISNUMBER(SEARCH("Control Type",E15))),"Switch","Infra")) -> Switch | P15: *ยังไม่ได้ถอด TCA2-009AS01 (FMSS 1 Port)
A16: 254 | B16: D1-041 | C16: Concourse B | D16: B2-031 | E16: Access Switch Type 4 | F16: 1 | G16: 1 | H16: 46107 | I16: 46174 | J16: Success | K16: =F16-G16 -> 0 | L16: =IF(F16=0,"",G16/F16) -> 1 | M16: =I16-TODAY() -> 61 | N16: =_xlfn.ISOWEEKNUM(I16) -> 23 | O16: =IF(ISNUMBER(SEARCH("Access Point",E16)),"AP",IF(OR(ISNUMBER(SEARCH("Switch",E16)),ISNUMBER(SEARCH("Control Type",E16))),"Switch","Infra")) -> Switch
A17: 707 | B17: AMF | C17: AMF2 | D17: - | E17: Access Point | F17: 6 | I17: 46190 | J17: On Plan | K17: =F17-G17 -> 6 | L17: =IF(F17=0,"",G17/F17) -> 0 | M17: =I17-TODAY() -> 77 | N17: =_xlfn.ISOWEEKNUM(I17) -> 25 | O17: =IF(ISNUMBER(SEARCH("Access Point",E17)),"AP",IF(OR(ISNUMBER(SEARCH("Switch",E17)),ISNUMBER(SEARCH("Control Type",E17))),"Switch","Infra")) -> AP
A18: 253 | B18: D1-041 | C18: Concourse B | D18: B2-031 | E18: Access Switch Type 2 | F18: 1 | G18: 1 | H18: 46107 | I18: 46174 | J18: Success | K18: =F18-G18 -> 0 | L18: =IF(F18=0,"",G18/F18) -> 1 | M18: =I18-TODAY() -> 61 | N18: =_xlfn.ISOWEEKNUM(I18) -> 23 | O18: =IF(ISNUMBER(SEARCH("Access Point",E18)),"AP",IF(OR(ISNUMBER(SEARCH("Switch",E18)),ISNUMBER(SEARCH("Control Type",E18))),"Switch","Infra")) -> Switch | P18: *ยังไม่ได้ถอด TCB2-031AS02 (FMSS 1 Port)
A19: 228 | B19: D1-041 | C19: Concourse C | D19: C2-044 | E19: Access Switch Type 4 | F19: 1 | G19: 1 | H19: 46107 | I19: 46132 | J19: Success | K19: =F19-G19 -> 0 | L19: =IF(F19=0,"",G19/F19) -> 1 | M19: =I19-TODAY() -> 19 | N19: =_xlfn.ISOWEEKNUM(I19) -> 17 | O19: =IF(ISNUMBER(SEARCH("Access Point",E19)),"AP",IF(OR(ISNUMBER(SEARCH("Switch",E19)),ISNUMBER(SEARCH("Control Type",E19))),"Switch","Infra")) -> Switch
A20: 227 | B20: D1-041 | C20: Concourse C | D20: C2-044 | E20: Access Switch Type 2 | F20: 1 | G20: 1 | H20: 46107 | I20: 46132 | J20: Success | K20: =F20-G20 -> 0 | L20: =IF(F20=0,"",G20/F20) -> 1 | M20: =I20-TODAY() -> 19 | N20: =_xlfn.ISOWEEKNUM(I20) -> 17 | O20: =IF(ISNUMBER(SEARCH("Access Point",E20)),"AP",IF(OR(ISNUMBER(SEARCH("Switch",E20)),ISNUMBER(SEARCH("Control Type",E20))),"Switch","Infra")) -> Switch | P20: *ยังไม่ได้ถอด TCC2-044AS01 (FMSS 1 Port)
A21: 209 | B21: D1-041 | C21: AIMS | D21: ห้องลูกค้า Server | E21: Access Switch Type 4 | F21: 4 | G21: 4 | H21: 46106 | I21: 46120 | J21: Success | K21: =F21-G21 -> 0 | L21: =IF(F21=0,"",G21/F21) -> 1 | M21: =I21-TODAY() -> 7 | N21: =_xlfn.ISOWEEKNUM(I21) -> 15 | O21: =IF(ISNUMBER(SEARCH("Access Point",E21)),"AP",IF(OR(ISNUMBER(SEARCH("Switch",E21)),ISNUMBER(SEARCH("Control Type",E21))),"Switch","Infra")) -> Switch
A22: 208 | B22: D1-041 | C22: AIMS | D22: ห้องลูกค้า Server | E22: Access Switch Type 2 | F22: 4 | G22: 4 | H22: 46106 | I22: 46120 | J22: Success | K22: =F22-G22 -> 0 | L22: =IF(F22=0,"",G22/F22) -> 1 | M22: =I22-TODAY() -> 7 | N22: =_xlfn.ISOWEEKNUM(I22) -> 15 | O22: =IF(ISNUMBER(SEARCH("Access Point",E22)),"AP",IF(OR(ISNUMBER(SEARCH("Switch",E22)),ISNUMBER(SEARCH("Control Type",E22))),"Switch","Infra")) -> Switch
A23: 715 | B23: AMF | C23: AMF3 | D23: - | E23: Access Point | F23: 2 | I23: 46192 | J23: On Plan | K23: =F23-G23 -> 2 | L23: =IF(F23=0,"",G23/F23) -> 0 | M23: =I23-TODAY() -> 79 | N23: =_xlfn.ISOWEEKNUM(I23) -> 25 | O23: =IF(ISNUMBER(SEARCH("Access Point",E23)),"AP",IF(OR(ISNUMBER(SEARCH("Switch",E23)),ISNUMBER(SEARCH("Control Type",E23))),"Switch","Infra")) -> AP
A24: 203 | B24: D1-041 | C24: AIMS | D24: Emergency Operation Center | E24: Access Switch Type 4 | F24: 1 | G24: 1 | H24: 46104 | I24: 46120 | J24: Success | K24: =F24-G24 -> 0 | L24: =IF(F24=0,"",G24/F24) -> 1 | M24: =I24-TODAY() -> 7 | N24: =_xlfn.ISOWEEKNUM(I24) -> 15 | O24: =IF(ISNUMBER(SEARCH("Access Point",E24)),"AP",IF(OR(ISNUMBER(SEARCH("Switch",E24)),ISNUMBER(SEARCH("Control Type",E24))),"Switch","Infra")) -> Switch
A25: 202 | B25: D1-041 | C25: AIMS | D25: Emergency Operation Center | E25: Access Switch Type 2 | F25: 1 | G25: 1 | H25: 46104 | I25: 46120 | J25: Success | K25: =F25-G25 -> 0 | L25: =IF(F25=0,"",G25/F25) -> 1 | M25: =I25-TODAY() -> 7 | N25: =_xlfn.ISOWEEKNUM(I25) -> 15 | O25: =IF(ISNUMBER(SEARCH("Access Point",E25)),"AP",IF(OR(ISNUMBER(SEARCH("Switch",E25)),ISNUMBER(SEARCH("Control Type",E25))),"Switch","Infra")) -> Switch
A26: 702 | B26: AMF | C26: AMF4 | D26: - | E26: Access Point | F26: 8 | G26: 8 | H26: 46109 | I26: 46189 | J26: Success | K26: =F26-G26 -> 0 | L26: =IF(F26=0,"",G26/F26) -> 1 | M26: =I26-TODAY() -> 76 | N26: =_xlfn.ISOWEEKNUM(I26) -> 25 | O26: =IF(ISNUMBER(SEARCH("Access Point",E26)),"AP",IF(OR(ISNUMBER(SEARCH("Switch",E26)),ISNUMBER(SEARCH("Control Type",E26))),"Switch","Infra")) -> AP
A27: 260 | B27: D1-041 | C27: Concourse B | D27: B3-008 | E27: Access Switch Type 4 | F27: 2 | G27: 2 | H27: 46101 | I27: 46135 | J27: Success | K27: =F27-G27 -> 0 | L27: =IF(F27=0,"",G27/F27) -> 1 | M27: =I27-TODAY() -> 22 | N27: =_xlfn.ISOWEEKNUM(I27) -> 17 | O27: =IF(ISNUMBER(SEARCH("Access Point",E27)),"AP",IF(OR(ISNUMBER(SEARCH("Switch",E27)),ISNUMBER(SEARCH("Control Type",E27))),"Switch","Infra")) -> Switch
A28: 259 | B28: D1-041 | C28: Concourse B | D28: B3-008 | E28: Access Switch Type 2 | F28: 2 | G28: 2 | H28: 46101 | I28: 46135 | J28: Success | K28: =F28-G28 -> 0 | L28: =IF(F28=0,"",G28/F28) -> 1 | M28: =I28-TODAY() -> 22 | N28: =_xlfn.ISOWEEKNUM(I28) -> 17 | O28: =IF(ISNUMBER(SEARCH("Access Point",E28)),"AP",IF(OR(ISNUMBER(SEARCH("Switch",E28)),ISNUMBER(SEARCH("Control Type",E28))),"Switch","Infra")) -> Switch
A29: 263 | B29: D1-041 | C29: Concourse B | D29: B4-003 | E29: Access Switch Type 4 | F29: 1 | G29: 1 | H29: 46101 | I29: 46135 | J29: Success | K29: =F29-G29 -> 0 | L29: =IF(F29=0,"",G29/F29) -> 1 | M29: =I29-TODAY() -> 22 | N29: =_xlfn.ISOWEEKNUM(I29) -> 17 | O29: =IF(ISNUMBER(SEARCH("Access Point",E29)),"AP",IF(OR(ISNUMBER(SEARCH("Switch",E29)),ISNUMBER(SEARCH("Control Type",E29))),"Switch","Infra")) -> Switch
A30: 262 | B30: D1-041 | C30: Concourse B | D30: B4-003 | E30: Access Switch Type 2 | F30: 1 | G30: 1 | H30: 46101 | I30: 46135 | J30: Success | K30: =F30-G30 -> 0 | L30: =IF(F30=0,"",G30/F30) -> 1 | M30: =I30-TODAY() -> 22 | N30: =_xlfn.ISOWEEKNUM(I30) -> 17 | O30: =IF(ISNUMBER(SEARCH("Access Point",E30)),"AP",IF(OR(ISNUMBER(SEARCH("Switch",E30)),ISNUMBER(SEARCH("Control Type",E30))),"Switch","Infra")) -> Switch
A31: 718 | B31: AMF | C31: AMF5 | D31: - | E31: Access Point | F31: 3 | I31: 46192 | J31: On Plan | K31: =F31-G31 -> 3 | L31: =IF(F31=0,"",G31/F31) -> 0 | M31: =I31-TODAY() -> 79 | N31: =_xlfn.ISOWEEKNUM(I31) -> 25 | O31: =IF(ISNUMBER(SEARCH("Access Point",E31)),"AP",IF(OR(ISNUMBER(SEARCH("Switch",E31)),ISNUMBER(SEARCH("Control Type",E31))),"Switch","Infra")) -> AP
A32: 234 | B32: D1-041 | C32: Concourse C | D32: C2-096 | E32: Access Switch Type 4 | F32: 1 | G32: 1 | H32: 46101 | I32: 46133 | J32: Success | K32: =F32-G32 -> 0 | L32: =IF(F32=0,"",G32/F32) -> 1 | M32: =I32-TODAY() -> 20 | N32: =_xlfn.ISOWEEKNUM(I32) -> 17 | O32: =IF(ISNUMBER(SEARCH("Access Point",E32)),"AP",IF(OR(ISNUMBER(SEARCH("Switch",E32)),ISNUMBER(SEARCH("Control Type",E32))),"Switch","Infra")) -> Switch
A33: 233 | B33: D1-041 | C33: Concourse C | D33: C2-096 | E33: Access Switch Type 2 | F33: 1 | G33: 1 | H33: 46101 | I33: 46133 | J33: Success | K33: =F33-G33 -> 0 | L33: =IF(F33=0,"",G33/F33) -> 1 | M33: =I33-TODAY() -> 20 | N33: =_xlfn.ISOWEEKNUM(I33) -> 17 | O33: =IF(ISNUMBER(SEARCH("Access Point",E33)),"AP",IF(OR(ISNUMBER(SEARCH("Switch",E33)),ISNUMBER(SEARCH("Control Type",E33))),"Switch","Infra")) -> Switch
A34: 721 | B34: AMF | C34: FFT | D34: - | E34: Access Point | F34: 1 | I34: 46195 | J34: On Plan | K34: =F34-G34 -> 1 | L34: =IF(F34=0,"",G34/F34) -> 0 | M34: =I34-TODAY() -> 82 | N34: =_xlfn.ISOWEEKNUM(I34) -> 26 | O34: =IF(ISNUMBER(SEARCH("Access Point",E34)),"AP",IF(OR(ISNUMBER(SEARCH("Switch",E34)),ISNUMBER(SEARCH("Control Type",E34))),"Switch","Infra")) -> AP
A35: 236 | B35: D1-041 | C35: Concourse C | D35: C2-120 | E35: Access Switch Type 4 | F35: 1 | G35: 1 | H35: 46101 | I35: 46133 | J35: Success | K35: =F35-G35 -> 0 | L35: =IF(F35=0,"",G35/F35) -> 1 | M35: =I35-TODAY() -> 20 | N35: =_xlfn.ISOWEEKNUM(I35) -> 17 | O35: =IF(ISNUMBER(SEARCH("Access Point",E35)),"AP",IF(OR(ISNUMBER(SEARCH("Switch",E35)),ISNUMBER(SEARCH("Control Type",E35))),"Switch","Infra")) -> Switch
A36: 235 | B36: D1-041 | C36: Concourse C | D36: C2-120 | E36: Access Switch Type 2 | F36: 1 | G36: 1 | H36: 46101 | I36: 46133 | J36: Success | K36: =F36-G36 -> 0 | L36: =IF(F36=0,"",G36/F36) -> 1 | M36: =I36-TODAY() -> 20 | N36: =_xlfn.ISOWEEKNUM(I36) -> 17 | O36: =IF(ISNUMBER(SEARCH("Access Point",E36)),"AP",IF(OR(ISNUMBER(SEARCH("Switch",E36)),ISNUMBER(SEARCH("Control Type",E36))),"Switch","Infra")) -> Switch
A37: 238 | B37: D1-041 | C37: Concourse C | D37: C3-009 | E37: Access Switch Type 4 | F37: 1 | G37: 1 | H37: 46101 | I37: 46133 | J37: Success | K37: =F37-G37 -> 0 | L37: =IF(F37=0,"",G37/F37) -> 1 | M37: =I37-TODAY() -> 20 | N37: =_xlfn.ISOWEEKNUM(I37) -> 17 | O37: =IF(ISNUMBER(SEARCH("Access Point",E37)),"AP",IF(OR(ISNUMBER(SEARCH("Switch",E37)),ISNUMBER(SEARCH("Control Type",E37))),"Switch","Infra")) -> Switch
A38: 237 | B38: D1-041 | C38: Concourse C | D38: C3-009 | E38: Access Switch Type 2 | F38: 1 | G38: 1 | H38: 46101 | I38: 46133 | J38: Success | K38: =F38-G38 -> 0 | L38: =IF(F38=0,"",G38/F38) -> 1 | M38: =I38-TODAY() -> 20 | N38: =_xlfn.ISOWEEKNUM(I38) -> 17 | O38: =IF(ISNUMBER(SEARCH("Access Point",E38)),"AP",IF(OR(ISNUMBER(SEARCH("Switch",E38)),ISNUMBER(SEARCH("Control Type",E38))),"Switch","Infra")) -> Switch
A39: 713 | B39: AMF | C39: WWT | D39: - | E39: Access Point | F39: 5 | I39: 46191 | J39: On Plan | K39: =F39-G39 -> 5 | L39: =IF(F39=0,"",G39/F39) -> 0 | M39: =I39-TODAY() -> 78 | N39: =_xlfn.ISOWEEKNUM(I39) -> 25 | O39: =IF(ISNUMBER(SEARCH("Access Point",E39)),"AP",IF(OR(ISNUMBER(SEARCH("Switch",E39)),ISNUMBER(SEARCH("Control Type",E39))),"Switch","Infra")) -> AP
A40: 241 | B40: D1-041 | C40: Concourse C | D40: C4-007 | E40: Access Switch Type 4 | F40: 1 | G40: 1 | H40: 46101 | I40: 46133 | J40: Success | K40: =F40-G40 -> 0 | L40: =IF(F40=0,"",G40/F40) -> 1 | M40: =I40-TODAY() -> 20 | N40: =_xlfn.ISOWEEKNUM(I40) -> 17 | O40: =IF(ISNUMBER(SEARCH("Access Point",E40)),"AP",IF(OR(ISNUMBER(SEARCH("Switch",E40)),ISNUMBER(SEARCH("Control Type",E40))),"Switch","Infra")) -> Switch
...

Sheet Summary
A1: SDA Installation Plan - Summary (Based on ภาคผนวก ค)
A2: Generated: 2026-02-01 06:26
A4: Fabric | B4: Start Date | C4: End Date | D4: Duration | E4: Total | F4: Switch | G4: AP | H4: Total/Day | I4: Switch/Day | J4: AP/Day | K4: Locations | L4: Rooms
A5: D1-041 | B5: 2026-02-14 | C5: 2026-06-10 | D5: 117 | E5: 712 | F5: 422 | G5: 290 | H5: 6.09 | I5: 3.61 | J5: 2.48 | K5: 19 | L5: 132
A6: CFZ | B6: 2026-02-22 | C6: 2026-04-08 | D6: 46 | E6: 187 | F6: 162 | G6: 25 | H6: 4.07 | I6: 3.52 | J6: 0.54 | K6: 31 | L6: 58
A7: T1-015 | B7: 2026-03-01 | C7: 2026-05-11 | D7: 72 | E7: 327 | F7: 283 | G7: 44 | H7: 4.54 | I7: 3.93 | J7: 0.61 | K7: 5 | L7: 65
A8: D1-091 | B8: 2026-03-08 | C8: 2026-04-23 | D8: 47 | E8: 145 | F8: 134 | G8: 11 | H8: 3.09 | I8: 2.85 | J8: 0.23 | K8: 10 | L8: 61
A9: RFF | B9: 2026-03-15 | C9: 2026-04-15 | D9: 32 | E9: 99 | F9: 67 | G9: 32 | H9: 3.09 | I9: 2.09 | J9: 1 | K9: 15 | L9: 31
A10: AMF | B10: 2026-03-15 | C10: 2026-04-21 | D10: 38 | E10: 114 | F10: 71 | G10: 43 | H10: 3 | I10: 1.87 | J10: 1.13 | K10: 12 | L10: 31
A11: PPW | B11: 2026-04-01 | C11: 2026-04-16 | D11: 16 | E11: 8 | F11: 8 | G11: 0 | H11: 0.5 | I11: 0.5 | J11: 0 | K11: 2 | L11: 3
A12: TOTAL | E12: 1592 | F12: 1147 | G12: 445

Sheet Type_Summary
A1: Device Type Summary by Fabric
A3: Device Type | B3: D1-041 | C3: CFZ | D3: T1-015 | E3: D1-091 | F3: RFF | G3: AMF | H3: PPW | I3: Total
A4: Access Control Type 1 | B4: 4 | C4: 0 | D4: 0 | E4: 0 | F4: 0 | G4: 0 | H4: 0 | I4: 4
A5: Access Point | B5: 290 | C5: 25 | D5: 44 | E5: 11 | F5: 32 | G5: 43 | H5: 0 | I5: 445
A6: Access Switch Type 1 | B6: 34 | C6: 0 | D6: 6 | E6: 0 | F6: 3 | G6: 2 | H6: 0 | I6: 45
A7: Access Switch Type 2 | B7: 164 | C7: 130 | D7: 140 | E7: 66 | F7: 40 | G7: 40 | H7: 4 | I7: 584
A8: Access Switch Type 3 | B8: 25 | C8: 0 | D8: 7 | E8: 0 | F8: 0 | G8: 5 | H8: 0 | I8: 37
A9: Access Switch Type 4 | B9: 128 | C9: 13 | D9: 100 | E9: 47 | F9: 17 | G9: 15 | H9: 0 | I9: 320
A10: Aggregation Switch Type 1 | B10: 2 | C10: 0 | D10: 0 | E10: 0 | F10: 0 | G10: 0 | H10: 0 | I10: 2
A11: Aggregation Switch Type 2 | B11: 25 | C11: 0 | D11: 13 | E11: 6 | F11: 1 | G11: 2 | H11: 0 | I11: 47
A12: Aggregation Switch Type 3 | B12: 18 | C12: 11 | D12: 13 | E12: 15 | F12: 2 | G12: 3 | H12: 0 | I12: 62
A13: Core Switch Type 1 | B13: 4 | C13: 0 | D13: 0 | E13: 0 | F13: 0 | G13: 0 | H13: 0 | I13: 4
A14: Distribute Switch Type 1 | B14: 4 | C14: 0 | D14: 2 | E14: 0 | F14: 2 | G14: 2 | H14: 0 | I14: 10
A15: Distribute Switch Type 2 | B15: 0 | C15: 2 | D15: 0 | E15: 0 | F15: 0 | G15: 0 | H15: 2 | I15: 4
... A23: TOTAL | B23: 712 | C23: 187 | D23: 327 | E23: 145 | F23: 99 | G23: 114 | H23: 8 | I23: 1592

Sheet Location_Summary
A1: Location Summary by Fabric - Installation Planning
A2: Generated: 2026-02-01 06:26 | Days allocated proportionally by device count
A4: Fabric | B4: Location | C4: Total | D4: Switch | E4: AP | F4: Days | G4: Total/Day | H4: Switch/Day | I4: AP/Day | J4: Rooms | K4: Start Date | L4: End Date | M4: Status
A5: D1-041 | B5: อาคารสำนักงานท่าอากาศยานสุวรรณภูมิ | C5: 318 | D5: 99 | E5: 219 | F5: 49 | G5: 6.49 | H5: 2.02 | I5: 4.47 | J5: 27 | K5: 2026-02-14 | L5: 2026-04-03 | M5: Pending
A6: D1-041 | B6: Concourse D | C6: 106 | D6: 106 | E6: 0 | F6: 16 | G6: 6.62 | H6: 6.62 | I6: 0 | J6: 29 | K6: 2026-04-04 | L6: 2026-04-19 | M6: Pending
A7: D1-041 | B7: Concourse A | C7: 71 | D7: 71 | E7: 0 | F7: 11 | G7: 6.45 | H7: 6.45 | I7: 0 | J7: 33 | K7: 2026-04-20 | L7: 2026-04-30 | M7: Pending
A8: D1-041 | B8: AIMS | C8: 64 | D8: 45 | E8: 19 | F8: 10 | G8: 6.4 | H8: 4.5 | I8: 1.9 | J8: 9 | K8: 2026-05-01 | L8: 2026-05-10 | M8: Pending
A9: D1-041 | B9: Concourse C | C9: 35 | D9: 35 | E9: 0 | F9: 5 | G9: 7 | H9: 7 | I9: 0 | J9: 13 | K9: 2026-05-11 | L9: 2026-05-15 | M9: Pending
A10: D1-041 | B10: Concourse B | C10: 26 | D10: 26 | E10: 0 | F10: 3 | G10: 8.67 | H10: 8.67 | I10: 0 | J10: 9 | K10: 2026-05-16 | L10: 2026-05-18 | M10: Pending
A11: D1-041 | B11: อาคารสถานีดับเพลิงและกู้ภัยฝั่งตะวันออก | C11: 18 | D11: 7 | E11: 11 | F11: 2 | G11: 9 | H11: 3.5 | I11: 5.5 | J11: 6 | K11: 2026-05-19 | L11: 2026-05-20 | M11: Pending
A12: D1-041 | B12: สำนักงานบริหารการก่อสร้าง อาคาร SBIA-NEWBULDING | C12: 14 | D12: 10 | E12: 4 | F12: 1 | G12: 14 | H12: 10 | I12: 4 | J12: 2 | K12: 2026-05-21 | L12: 2026-05-21 | M12: Pending
A13: D1-041 | B13: สำนักงานบริหารการก่อสร้าง อาคาร 2 | C13: 13 | D13: 4 | E13: 9 | F13: 1 | G13: 13 | H13: 4 | I13: 9 | J13: 2 | K13: 2026-05-22 | L13: 2026-05-22 | M13: Pending
A14: D1-041 | B14: สำนักงานบริหารการก่อสร้าง อาคาร 3 | C14: 12 | D14: 3 | E14: 9 | F14: 1 | G14: 12 | H14: 3 | I14: 9 | J14: 2 | K14: 2026-05-23 | L14: 2026-05-23 | M14: Pending
A15: D1-041 | B15: สำนักงานบริหารการก่อสร้าง อาคาร PMC | C15: 10 | D15: 0 | E15: 10 | F15: 1 | G15: 10 | H15: 0 | I15: 10 | J15: 1 | K15: 2026-05-24 | L15: 2026-05-24 | M15: Pending
A16: D1-041 | B16: สำนักงานบริหารการก่อสร้าง อาคาร 1 | C16: 10 | D16: 4 | E16: 6 | F16: 1 | G16: 10 | H16: 4 | I16: 6 | J16: 2 | K16: 2026-05-25 | L16: 2026-05-25 | M16: Pending
... A98: PPW | B98: Power house 01L | C98: 2 | D98: 2 | E98: 0 | F98: 4 | G98: 0.5 | H98: 0.5 | I98: 0 | J98: 1 | K98: 2026-04-13 | L98: 2026-04-16 | M98: Pending
A99: TOTAL | B99: 94 locations | C99: 1592 | D99: 1147 | E99: 445 | J99: 370

Sheet Room_Summary
A1: Room Summary by Location - Installation Tracking
A2: Generated: 2026-02-01 06:26 | Complete room by room, rate balanced
A4: Fabric | B4: Location | C4: Room | D4: Total | E4: Switch | F4: AP | G4: Days | H4: Total/Day | I4: Start Date | J4: End Date | K4: Work Day | L4: Status | M4: Team | N4: Notes
A5: D1-041 | B5: อาคารสำนักงานท่าอากาศยานสุวรรณภูมิ | C5: - | D5: 219 | E5: 0 | F5: 219 | G5: 36 | H5: 6.08 | I5: 2026-02-14 | J5: 2026-03-21 | K5: 1 | L5: Pending
A6: D1-041 | B6: อาคารสำนักงานท่าอากาศยานสุวรรณภูมิ | C6: 202ELE | D6: 10 | E6: 10 | F6: 0 | G6: 2 | H6: 5 | I6: 2026-03-22 | J6: 2026-03-23 | K6: 37 | L6: Pending
A7: D1-041 | B7: อาคารสำนักงานท่าอากาศยานสุวรรณภูมิ | C7: 204COM Room | D7: 8 | E7: 8 | F7: 0 | G7: 1 | H7: 8 | I7: 2026-03-24 | J7: 2026-03-24 | K7: 39 | L7: Pending
A8: D1-041 | B8: อาคารสำนักงานท่าอากาศยานสุวรรณภูมิ | C8: 500COM Room | D8: 7 | E8: 7 | F8: 0 | G8: 1 | H8: 7 | I8: 2026-03-24 | J8: 2026-03-24 | K8: 39 | L8: Pending
A9: D1-041 | B9: อาคารสำนักงานท่าอากาศยานสุวรรณภูมิ | C9: ห้องส่วนระบบเครือข่าย | D9: 7 | E9: 7 | F9: 0 | G9: 1 | H9: 7 | I9: 2026-03-25 | J9: 2026-03-25 | K9: 40 | L9: Pending
A10: D1-041 | B10: อาคารสำนักงานท่าอากาศยานสุวรรณภูมิ | C10: 402ELE | D10: 6 | E10: 6 | F10: 0 | G10: 1 | H10: 6 | I10: 2026-03-26 | J10: 2026-03-26 | K10: 41 | L10: Pending
A11: D1-041 | B11: อาคารสำนักงานท่าอากาศยานสุวรรณภูมิ | C11: 105 Computer-Security Department | D11: 6 | E11: 6 | F11: 0 | G11: 1 | H11: 6 | I11: 2026-03-27 | J11: 2026-03-27 | K11: 42 | L11: Pending
A12: D1-041 | B12: อาคารสำนักงานท่าอากาศยานสุวรรณภูมิ | C12: 304COM Room | D12: 5 | E12: 5 | F12: 0 | G12: 1 | H12: 5 | I12: 2026-03-28 | J12: 2026-03-28 | K12: 43 | L12: Pending
A13: D1-041 | B13: อาคารสำนักงานท่าอากาศยานสุวรรณภูมิ | C13: 201ELE | D13: 4 | E13: 4 | F13: 0 | G13: 1 | H13: 4 | I13: 2026-03-29 | J13: 2026-03-29 | K13: 44 | L13: Pending
A14: D1-041 | B14: อาคารสำนักงานท่าอากาศยานสุวรรณภูมิ | C14: 301ELE | D14: 4 | E14: 4 | F14: 0 | G14: 1 | H14: 4 | I14: 2026-03-30 | J14: 2026-03-30 | K14: 45 | L14: Pending
A15: D1-041 | B15: อาคารสำนักงานท่าอากาศยานสุวรรณภูมิ | C15: Canteen | D15: 4 | E15: 4 | F15: 0 | G15: 1 | H15: 4 | I15: 2026-03-31 | J15: 2026-03-31 | K15: 46 | L15: Pending
A16: D1-041 | B16: อาคารสำนักงานท่าอากาศยานสุวรรณภูมิ | C16: 603FAN2 | D16: 4 | E16: 4 | F16: 0 | G16: 1 | H16: 4 | I16: 2026-04-01 | J16: 2026-04-01 | K16: 47 | L16: Pending
... A415: PPW | B415: Power house 01L | C415: 01L-FL.1 | D415: 2 | E415: 2 | F415: 0 | G415: 4 | H415: 0.5 | I415: 2026-04-13 | J415: 2026-04-16 | K415: 13 | L415: Pending
A416: TOTAL | C416: 370 rooms | D416: 1592 | E416: 1147 | F416: 445

Sheet Cross_Check
A1: Cross-Check: ภาคผนวก ค vs Device Install Old-New
A3: Device Type | B3: ภาคผนวก ค | C3: Device Install | D3: Diff | E3: Status
A4: Access Control Type 1 | B4: 4 | C4: 4 | D4: 0 | E4: ✅ OK
A5: Access Switch Type 1 | B5: 45 | C5: 39 | D5: -6 | E5: ⚠️ Check
A6: Access Switch Type 2 | B6: 584 | C6: 550 | D6: -34 | E6: ❌ Gap
A7: Access Switch Type 3 | B7: 37 | C7: 30 | D7: -7 | E7: ⚠️ Check
A8: Access Switch Type 4 | B8: 320 | C8: 299 | D8: -21 | E8: ❌ Gap
A9: Aggregation Switch Type 1 | B9: 2 | C9: 2 | D9: 0 | E9: ✅ OK
A10: Aggregation Switch Type 2 | B10: 47 | C10: 47 | D10: 0 | E10: ✅ OK
A11: Aggregation Switch Type 3 | B11: 62 | C11: 64 | D11: 2 | E11: ✅ OK
A12: Core Switch Type 1 | B12: 4 | C12: 4 | D12: 0 | E12: ✅ OK
A13: Distribute Switch Type 1 | B13: 10 | C13: 10 | D13: 0 | E13: ✅ OK
A14: Distribute Switch Type 2 | B14: 4 | C14: 0 | D14: -4 | E14: ✅ OK
A15: Extranet Switch Type 1 | B15: 2 | C15: 2 | D15: 0 | E15: ✅ OK
... A22: อุปกรณ์กระจายสัญญาณเครือข่ายรองแบบที่ 3 (Distribute Switch Type 2) | B22: 0 | C22: 4 | D22: 4 | E22: ✅ OK
A23: TOTAL (no AP) | B23: 1147 | C23: 1077 | D23: -70

Sheet Normalized_Data
A1: Normalized Data from ภาคผนวก ค
A3: Fabric | B3: Location | C3: Room | D3: Device Type | E3: Device Type (Thai) | F3: Quantity
A4: AMF | B4: AFD | C4: Computer Room | D4: Access Switch Type 2 | E4: อุปกรณ์กระจายสัญญาณเครือข่ายแบบที่ 2 (Access Switch Type 2) | F4: 2
A5: AMF | B5: AMF1 | C5: - | D5: Access Point | E5: อุปกรณ์กระจายสัญญาณเครือข่ายไร้สาย (Access Point) | F5: 18
A6: AMF | B6: AMF1 | C6: AMF1 FL.2 | D6: Distribute Switch Type 1 | E6: อุปกรณ์กระจายสัญญาณเครือข่ายรองแบบที่ 1 (Distribute Switch Type 1) | F6: 2
A7: AMF | B7: AMF1 | C7: AMF1 FL.2 | D7: Wireless Controller | E7: อุปกรณ์ควบคุมการกระจายสัญญาณเครือข่ายไร้สาย (Wireless Controller) | F7: 2
A8: AMF | B8: AMF1 | C8: AMF1-FL.3 | D8: Access Switch Type 2 | E8: อุปกรณ์กระจายสัญญาณเครือข่ายแบบที่ 2 (Access Switch Type 2) | F8: 2
A9: AMF | B9: AMF1 | C9: AMF11 | D9: Access Switch Type 2 | E9: อุปกรณ์กระจายสัญญาณเครือข่ายแบบที่ 2 (Access Switch Type 2) | F9: 1
A10: AMF | B10: AMF1 | C10: AMF11 | D10: Access Switch Type 3 | E10: อุปกรณ์กระจายสัญญาณเครือข่ายแบบที่ 3 (Access Switch Type 3) | F10: 1
A11: AMF | B11: AMF1 | C11: AMF12 | D11: Access Switch Type 3 | E11: อุปกรณ์กระจายสัญญาณเครือข่ายแบบที่ 3 (Access Switch Type 3) | F11: 2
A12: AMF | B12: AMF1 | C12: AMF12 Core Room | D12: Aggregation Switch Type 2 | E12: อุปกรณ์กระจายสัญญาณเครือข่ายรวมแบบที่ 2 (Aggregation Switch Type 2) | F12: 2
A13: AMF | B13: AMF1 | C13: AMF13 | D13: Access Switch Type 1 | E13: อุปกรณ์กระจายสัญญาณเครือข่ายแบบที่ 1 (Access Switch Type 1) | F13: 2
A14: AMF | B14: AMF1 | C14: AMF13 | D14: Access Switch Type 3 | E14: อุปกรณ์กระจายสัญญาณเครือข่ายแบบที่ 3 (Access Switch Type 3) | F14: 2
A15: AMF | B15: AMF1 | C15: Air Conditioned Room | D15: Access Switch Type 2 | E15: อุปกรณ์กระจายสัญญาณเครือข่ายแบบที่ 2 (Access Switch Type 2) | F15: 3
... A751: T1-015 | B751: อาคารผู้โดยสาร | C751: T6-014 | D751: Access Switch Type 4 | E751: อุปกรณ์กระจายสัญญาณเครือข่ายแบบที่ 4 (Access Switch Type 4) | F751: 1

Sheet D1-041_Detail
A1: Fabric D1-041 - Installation Details
A2: Period: 2026-02-14 to 2026-06-10 | Total: 712 devices (AP: 290) | Proportional scheduling
A4: Location | B4: Room | C4: Device Type | D4: Qty | E4: Qty. Success | F4: Scheduled Date | G4: Install Date | H4: Status
A5: อาคารสำนักงานท่าอากาศยานสุวรรณภูมิ | B5: - | C5: Access Point | D5: 219 | F5: 46067 | H5: Pending
A6: อาคารสำนักงานท่าอากาศยานสุวรรณภูมิ | B6: 101ELE | C6: Access Switch Type 3 | D6: 4 | F6: 46068 | H6: Pending
A7: อาคารสำนักงานท่าอากาศยานสุวรรณภูมิ | B7: 104LAN Air-Condition | C7: Access Switch Type 2 | D7: 2 | F7: 46072 | H7: On Plan
A8: อาคารสำนักงานท่าอากาศยานสุวรรณภูมิ | B8: 104LAN Server Room | C8: Aggregation Switch Type 1 | D8: 2 | E8: 2 | F8: 46070 | G8: 46063 | H8: Success
A9: อาคารสำนักงานท่าอากาศยานสุวรรณภูมิ | B9: 105 Computer-Security Department | C9: Access Switch Type 1 | D9: 5 | F9: 46071 | H9: Pending
A10: อาคารสำนักงานท่าอากาศยานสุวรรณภูมิ | B10: 105 Computer-Security Department | C10: Access Switch Type 4 | D10: 1 | F10: 46072 | H10: Pending
A11: อาคารสำนักงานท่าอากาศยานสุวรรณภูมิ | B11: 201ELE | C11: Access Switch Type 3 | D11: 4 | F11: 46073 | H11: Pending
A12: อาคารสำนักงานท่าอากาศยานสุวรรณภูมิ | B12: 202ELE | C12: Access Switch Type 1 | D12: 3 | F12: 46074 | H12: Pending
A13: อาคารสำนักงานท่าอากาศยานสุวรรณภูมิ | B13: 202ELE | C13: Access Switch Type 4 | D13: 7 | F13: 46075 | H13: Pending
A14: อาคารสำนักงานท่าอากาศยานสุวรรณภูมิ | B14: 204COM Room | C14: Access Switch Type 1 | D14: 5 | F14: 46072 | H14: On Plan
A15: อาคารสำนักงานท่าอากาศยานสุวรรณภูมิ | B15: 204COM Room | C15: Access Switch Type 2 | D15: 2 | F15: 46072 | H15: On Plan
A16: อาคารสำนักงานท่าอากาศยานสุวรรณภูมิ | B16: 204COM Room | C16: Access Switch Type 4 | D16: 1 | F16: 46072 | H16: On Plan
A17: อาคารสำนักงานท่าอากาศยานสุวรรณภูมิ | B17: 301ELE | C17: Access Switch Type 3 | D17: 4 | F17: 46069 | H17: On Plan
A18: อาคารสำนักงานท่าอากาศยานสุวรรณภูมิ | B18: 302ELE | C18: Access Switch Type 1 | D18: 1 | F18: 46069 | H18: On Plan
A19: อาคารสำนักงานท่าอากาศยานสุวรรณภูมิ | B19: 302ELE | C19: Access Switch Type 4 | D19: 2 | F19: 46069 | H19: On Plan
A20: อาคารสำนักงานท่าอากาศยานสุวรรณภูมิ | B20: 304COM Room | C20: Access Switch Type 1 | D20: 4 | F20: 46083 | H20: Pending
... A246: Concourse B | B246: B1-024 | C246: Access Switch Type 4 | D246: 1 | F246: 46070 | H246: On Plan
A247: Concourse B | B247: B1-024 | C247: Aggregation Switch Type 2 | D247: 2 | F247: 46158 | G247: 46062 | H247: Success
A248: Concourse B | B248: B1-039 | C248: Access Switch Type 2 | D248: 1 | F248: 46158 | H248: Pending
A249: Concourse B | B249: B1-039 | C249: Access Switch Type 4 | D249: 1 | F249: 46158 | H249: Pending
A250: Concourse B | B250: B1-039 | C250: Aggregation Switch Type 3 | D250: 1 | F250: 46158 | H250: Pending
A251: Concourse B | B251: B1-049 | C251: Access Switch Type 2 | D251: 1 | F251: 46158 | H251: Pending
A252: Concourse B | B252: B1-049 | C252: Access Switch Type 4 | D252: 1 | F252: 46158 | H252: Pending
A253: Concourse B | B253: B1-049 | C253: Aggregation Switch Type 3 | D253: 1 | F253: 46159 | H253: Pending
A254: Concourse B | B254: B2-010 | C254: Access Switch Type 2 | D254: 2 | F254: 46069 | H254: On Plan
A255: Concourse B | B255: B2-010 | C255: Access Switch Type 4 | D255: 1 | F255: 46069 | H255: On Plan
A256: Concourse B | B256: B2-031 | C256: Access Switch Type 2 | D256: 1 | F256: 46069 | H256: On Plan
A257: Concourse B | B257: B2-031 | C257: Access Switch Type 4 | D257: 1 | F257: 46069 | H257: On Plan
A258: Concourse B | B258: B2-062 | C258: Access Switch Type 2 | D258: 1 | F258: 46159 | H258: Pending
A259: Concourse B | B259: B2-062 | C259: Access Switch Type 4 | D259: 1 | F259: 46159 | H259: Pending
... A301: อาคารโรงสูบน้ำฝั่งตะออก | B301: Unknown Room | C301: Access Switch Type 2 | D301: 1 | F301: 46174 | H301: Pending
A304: Summary by Device Type
A305: Access Point | B305: 290
A306: Access Switch Type 2 | B306: 164
A307: Access Switch Type 4 | B307: 128
A308: Access Switch Type 1 | B308: 34
A309: Access Switch Type 3 | B309: 25
...

Sheet CFZ_Detail
A1: Fabric CFZ - Installation Details
A2: Period: 2026-02-22 to 2026-04-08 | Total: 187 devices (AP: 25) | Proportional scheduling
A4: Location | B4: Room | C4: Device Type | D4: Qty | E4: Scheduled Date | F4: Status
A5: อาคาร BFZ | B5: (BF-Z) COMM. RM. | C5: Access Switch Type 2 | D5: 4 | E5: 2026-02-22 | F5: Pending
A6: อาคาร BFZ | B6: (BF-Z) COMM. RM. | C6: Access Switch Type 4 | D6: 2 | E6: 2026-02-23 | F6: Pending
A7: อาคาร BFZ | B7: (BF-Z) MDB COMM | C7: Access Switch Type 2 | D7: 8 | E7: 2026-02-24 | F7: Pending
A8: อาคาร BFZ | B8: (BF-Z) MDB COMM | C8: Access Switch Type 4 | D8: 4 | E8: 2026-02-25 | F8: Pending
A9: อาคาร BFZ | B9: - | C9: Access Point | D9: 24 | E9: 2026-02-26 | F9: Pending
A10: อาคาร BFZ | B10: BFZ FL.7 | C10: Access Switch Type 4 | D10: 2 | E10: 2026-02-27 | F10: Pending
A11: อาคาร BFZ | B11: BFZ-7 | C11: Access Switch Type 2 | D11: 4 | E11: 2026-02-28 | F11: Pending
A12: อาคาร BFZ | B12: CCTV ROOM | C12: Access Switch Type 2 | D12: 1 | E12: 2026-03-01 | F12: Pending
A13: อาคาร BFZ | B13: Data Center | C13: Access Switch Type 2 | D13: 7 | E13: 2026-03-02 | F13: Pending
A14: อาคาร BFZ | B14: Data Center | C14: Access Switch Type 4 | D14: 1 | E14: 2026-03-03 | F14: Pending
A15: อาคาร BFZ | B15: Data Center | C15: Router | D15: 2 | E15: 2026-03-04 | F15: Pending
A16: อาคาร BC-1 | B16: (BC-1) COMM. | C16: Access Switch Type 2 | D16: 4 | E16: 2026-03-05 | F16: Pending
... A76: อาคาร Gatehouse 2 | B76: GH-2 FL.1 | C76: Access Switch Type 2 | D76: 1 | E76: 2026-04-08 | F76: Pending
A79: Summary by Device Type
A80: Access Switch Type 2 | B80: 130
A81: Access Point | B81: 25
A82: Access Switch Type 4 | B82: 13
A83: Aggregation Switch Type 3 | B83: 11
A84: Router | B84: 4
A85: Distribute Switch Type 2 | B85: 2
A86: Wireless Controller | B86: 2

Sheet T1-015_Detail
A1: Fabric T1-015 - Installation Details
A2: Period: 2026-03-01 to 2026-05-11 | Total: 327 devices (AP: 44) | Proportional scheduling
A4: Location | B4: Room | C4: Device Type | D4: Qty | E4: Scheduled Date | F4: Status
A5: อาคารผู้โดยสาร | B5: - | C5: Access Point | D5: 44 | E5: 2026-03-01 | F5: Pending
A6: อาคารผู้โดยสาร | B6: CheckinRow A Island-1 | C6: Access Switch Type 2 | D6: 3 | E6: 2026-03-01 | F6: Pending
A7: อาคารผู้โดยสาร | B7: CheckinRow A Island-1 | C7: Access Switch Type 4 | D7: 2 | E7: 2026-03-01 | F7: Pending
A8: อาคารผู้โดยสาร | B8: CheckinRow C Island-2 | C8: Access Switch Type 2 | D8: 3 | E8: 2026-03-02 | F8: Pending
A9: อาคารผู้โดยสาร | B9: CheckinRow C Island-2 | C9: Access Switch Type 4 | D9: 3 | E9: 2026-03-02 | F9: Pending
A10: อาคารผู้โดยสาร | B10: CheckinRow E Island-3 | C10: Access Switch Type 2 | D10: 3 | E10: 2026-03-02 | F10: Pending
A11: อาคารผู้โดยสาร | B11: CheckinRow E Island-3 | C11: Access Switch Type 4 | D11: 3 | E11: 2026-03-03 | F11: Pending
A12: อาคารผู้โดยสาร | B12: CheckinRow G Island-4 | C12: Access Switch Type 2 | D12: 3 | E12: 2026-03-03 | F12: Pending
A13: อาคารผู้โดยสาร | B13: CheckinRow G Island-4 | C13: Access Switch Type 4 | D13: 3 | E13: 2026-03-04 | F13: Pending
A14: อาคารผู้โดยสาร | B14: CheckinRow J Island-5 | C14: Access Switch Type 2 | D14: 3 | E14: 2026-03-04 | F14: Pending
A15: อาคารผู้โดยสาร | B15: CheckinRow J Island-5 | C15: Access Switch Type 4 | D15: 3 | E15: 2026-03-04 | F15: Pending
A16: อาคารผู้โดยสาร | B16: CheckinRow L Island-6 | C16: Access Switch Type 2 | D16: 3 | E16: 2026-03-05 | F16: Pending
... A155: Terminal | B155: T1-015 | C155: Wireless Controller | D155: 2 | E155: 2026-05-08 | F155: Pending
A158: Summary by Device Type
A159: Access Switch Type 2 | B159: 140
A160: Access Switch Type 4 | B160: 100
A161: Access Point | B161: 44
A162: Aggregation Switch Type 2 | B162: 13
A163: Aggregation Switch Type 3 | B163: 13
A164: Access Switch Type 3 | B164: 7
A165: Access Switch Type 1 | B165: 6
A166: Distribute Switch Type 1 | B166: 2
A167: Wireless Controller | B167: 2

Sheet D1-091_Detail
A1: Fabric D1-091 - Installation Details
A2: Period: 2026-03-08 to 2026-04-23 | Total: 145 devices (AP: 11) | Proportional scheduling
A4: Location | B4: Room | C4: Device Type | D4: Qty | E4: Scheduled Date | F4: Status
A5: Concourse G | B5: G1-028 | C5: Access Switch Type 2 | D5: 2 | E5: 2026-03-08 | F5: Pending
A6: Concourse G | B6: G1-028 | C6: Access Switch Type 4 | D6: 1 | E6: 2026-03-08 | F6: Pending
A7: Concourse G | B7: G1-028 | C7: Aggregation Switch Type 3 | D7: 1 | E7: 2026-03-08 | F7: Pending
A8: Concourse G | B8: G1-041 | C8: Access Switch Type 2 | D8: 1 | E8: 2026-03-08 | F8: Pending
A9: Concourse G | B9: G1-041 | C9: Access Switch Type 4 | D9: 1 | E9: 2026-03-09 | F9: Pending
A10: Concourse G | B10: G1-041 | C10: Aggregation Switch Type 2 | D10: 1 | E10: 2026-03-09 | F10: Pending
A11: Concourse G | B11: G1-045 | C11: Access Switch Type 2 | D11: 1 | E11: 2026-03-09 | F11: Pending
A12: Concourse G | B12: G1-050 | C12: Access Switch Type 2 | D12: 1 | E12: 2026-03-10 | F12: Pending
A13: Concourse G | B13: G1-050 | C13: Access Switch Type 4 | D13: 1 | E13: 2026-03-10 | F13: Pending
A14: Concourse G | B14: G1-057 | C14: Access Switch Type 2 | D14: 1 | E14: 2026-03-10 | F14: Pending
A15: Concourse G | B15: G1-057 | C15: Access Switch Type 4 | D15: 1 | E15: 2026-03-10 | F15: Pending
A16: Concourse G | B16: G1-057 | C16: Aggregation Switch Type 2 | D16: 1 | E16: 2026-03-11 | F16: Pending
... A131: อาคารฝ่ายบริการอุปกรณ์ภาคพื้น การบินไทย | B131: Electrical Control Room | C131: Access Switch Type 2 | D131: 1 | E131: 2026-04-21 | F131: Pending
A134: Summary by Device Type
A135: Access Switch Type 2 | B135: 66
A136: Access Switch Type 4 | B136: 47
A137: Aggregation Switch Type 3 | B137: 15
A138: Access Point | B138: 11
A139: Aggregation Switch Type 2 | B139: 6

Sheet RFF_Detail
A1: Fabric RFF - Installation Details
A2: Period: 2026-03-15 to 2026-04-15 | Total: 99 devices (AP: 32) | Proportional scheduling
A4: Location | B4: Room | C4: Device Type | D4: Qty | E4: Scheduled Date | F4: Status
A5: RFF | B5: - | C5: Access Point | D5: 25 | E5: 2026-03-15 | F5: Pending
A6: RFF | B6: Electical High Voltage Room | C6: Access Switch Type 2 | D6: 2 | E6: 2026-03-15 | F6: Pending
A7: RFF | B7: Electical Room | C7: Access Switch Type 2 | D7: 4 | E7: 2026-03-16 | F7: Pending
A8: RFF | B8: Fl.2 | C8: Access Switch Type 4 | D8: 3 | E8: 2026-03-17 | F8: Pending
A9: RFF | B9: Fl.3 | C9: Access Switch Type 4 | D9: 1 | E9: 2026-03-18 | F9: Pending
A10: RFF | B10: Node 4 | C10: Distribute Switch Type 1 | D10: 2 | E10: 2026-03-19 | F10: Pending
A11: RFF | B11: RFF FL.1 | C11: Access Switch Type 1 | D11: 1 | E11: 2026-03-20 | F11: Pending
A12: RFF | B12: RFF FL.1 | C12: Wireless Controller | D12: 2 | E12: 2026-03-21 | F12: Pending
A13: RFF | B13: RFF FL.2 | C13: Access Switch Type 1 | D13: 2 | E13: 2026-03-22 | F13: Pending
A14: RFF | B14: งานควบคุมและมาตรฐาน | C14: Access Switch Type 4 | D14: 1 | E14: 2026-03-23 | F14: Pending
A15: RFF | B15: ตรวจถังดับเพลิง | C15: Aggregation Switch Type 2 | D15: 1 | E15: 2026-03-24 | F15: Pending
A16: RFF | B16: ห้องประชุมใหญ่ | C16: Access Switch Type 4 | D16: 1 | E16: 2026-03-25 | F16: Pending
... A43: TGO | B43: Computer Operations center | C43: Access Switch Type 2 | D43: 1 | E43: 2026-04-15 | F43: Pending
A46: Summary by Device Type
A47: Access Switch Type 2 | B47: 40
A48: Access Point | B48: 32
A49: Access Switch Type 4 | B49: 17
A50: Access Switch Type 1 | B50: 3
A51: Aggregation Switch Type 3 | B51: 2
A52: Distribute Switch Type 1 | B52: 2
A53: Wireless Controller | B53: 2
A54: Aggregation Switch Type 2 | B54: 1

Sheet AMF_Detail
A1: Fabric AMF - Installation Details
A2: Period: 2026-03-15 to 2026-04-21 | Total: 114 devices (AP: 43) | Proportional scheduling
A4: Location | B4: Room | C4: Device Type | D4: Qty | E4: Scheduled Date | F4: Status
A5: AMF1 | B5: - | C5: Access Point | D5: 18 | E5: 2026-03-15 | F5: Pending
A6: AMF1 | B6: AMF1 FL.2 | C6: Distribute Switch Type 1 | D6: 2 | E6: 2026-03-16 | F6: Pending
A7: AMF1 | B7: AMF1 FL.2 | C7: Wireless Controller | D7: 2 | E7: 2026-03-17 | F7: Pending
A8: AMF1 | B8: AMF1-FL.3 | C8: Access Switch Type 2 | D8: 2 | E8: 2026-03-18 | F8: Pending
A9: AMF1 | B9: AMF11 | C9: Access Switch Type 2 | D9: 1 | E9: 2026-03-19 | F9: Pending
A10: AMF1 | B10: AMF11 | C10: Access Switch Type 3 | D10: 1 | E10: 2026-03-20 | F10: Pending
A11: AMF1 | B11: AMF12 | C11: Access Switch Type 3 | D11: 2 | E11: 2026-03-21 | F11: Pending
A12: AMF1 | B12: AMF12 Core Room | C12: Aggregation Switch Type 2 | D12: 2 | E12: 2026-03-23 | F12: Pending
A13: AMF1 | B13: AMF13 | C13: Access Switch Type 1 | D13: 2 | E13: 2026-03-24 | F13: Pending
A14: AMF1 | B14: AMF13 | C14: Access Switch Type 3 | D14: 2 | E14: 2026-03-25 | F14: Pending
A15: AMF1 | B15: Air Conditioned Room | C15: Access Switch Type 2 | D15: 3 | E15: 2026-03-26 | F15: Pending
A16: AMF1 | B16: Core Node Room | C16: Access Switch Type 2 | D16: 11 | E16: 2026-03-27 | F16: Pending
... A49: อาคารรอบนอก | B49: ห้องควบคุมระบบบำบัดน้ำเสีย | C49: Access Switch Type 4 | D49: 1 | E49: 2026-04-16 | F49: Pending
A52: Summary by Device Type
A53: Access Point | B53: 43
A54: Access Switch Type 2 | B54: 40
A55: Access Switch Type 4 | B55: 15
A56: Access Switch Type 3 | B56: 5
A57: Aggregation Switch Type 3 | B57: 3
A58: Access Switch Type 1 | B58: 2
A59: Aggregation Switch Type 2 | B59: 2
A60: Distribute Switch Type 1 | B60: 2
A61: Wireless Controller | B61: 2

Sheet PPW_Detail
A1: Fabric PPW - Installation Details
A2: Period: 2026-04-01 to 2026-04-16 | Total: 8 devices (AP: 0) | Proportional scheduling
